<?xml version="1.0"?>
<gazebo version='1.0'>
<model name="Aibo" static="1">

  <link name="base_link" >
      <inertial mass="1.0">
        <inertia ixx='1' ixy='0' ixz='0' iyy='1' iyz='0' izz='1'/>
      </inertial>
      <collision name="geom">
        <geometry>
         <cylinder radius="0.055" length="0.240"/>
        </geometry>
	<origin pose="0.0 0 0 0 1.5707 1.5707"/>
      </collision>
      <visual name="visual">
        <geometry>
          <cylinder radius="0.055" length="0.240"/>
        </geometry>
	<origin pose="0.0 0 0 0 1.5707 1.5707"/>
      </visual>
    </link>


<!-- S'ha de pensar que l'origen de l'articulacio es en referencia al pare d'aquesta, despres si es vol que l'articulacio no estigui en el centre del link s'ha de moure el visual -->

<!-- Part superior, primer l'esfera per l'articulacio per fer el gir en l'eix y, despres el cilindre que rotara al voltant de l'eix x -->

<!--Eix y-->

  <link name="RF_up_leg_rot_y" >
      <collision name="geom">
        <geometry>
          <sphere radius="0.005"/>
        </geometry>
      </collision>
   
      <visual name="visual">
        <geometry>
          <sphere radius="0.005"/>
        </geometry>
      </visual>
      <inertial mass="0.1">
        <inertia ixx='1' ixy='0' ixz='0' iyy='1' iyz='0' izz='1'/>
      </inertial>
    </link>

  <link name="LF_up_leg_rot_y" >
      <collision name="geom">
        <geometry>
          <sphere radius="0.005"/>
        </geometry>
      </collision>
   
      <visual name="visual">
        <geometry>
          <sphere radius="0.005"/>
        </geometry>
      </visual>
      <inertial mass="0.1">
        <inertia ixx='1' ixy='0' ixz='0' iyy='1' iyz='0' izz='1'/>
      </inertial>
    </link>

  <link name="RB_up_leg_rot_y" >
      <collision name="geom">
        <geometry>
          <sphere radius="0.005"/>
        </geometry>
      </collision>
   
      <visual name="visual">
        <geometry>
          <sphere radius="0.005"/>
        </geometry>
      </visual>
      <inertial mass="0.1">
        <inertia ixx='1' ixy='0' ixz='0' iyy='1' iyz='0' izz='1'/>
      </inertial>
    </link>

  <link name="LB_up_leg_rot_y" >
      <collision name="geom">
        <geometry>
          <sphere radius="0.005"/>
        </geometry>
      </collision>
   
      <visual name="visual">
        <geometry>
          <sphere radius="0.005"/>
        </geometry>
      </visual>
      <inertial mass="0.1">
        <inertia ixx='1' ixy='0' ixz='0' iyy='1' iyz='0' izz='1'/>
      </inertial>
    </link>


<!--Eix x-->

  <link name="RF_up_leg_rot_x" >
      <collision name="geom">
        <geometry>
          <cylinder radius="0.020" length="0.075"/>
        </geometry>
      </collision>
   
      <visual name="visual">
        <geometry>
          <cylinder radius="0.020" length="0.075"/>
        </geometry>
      </visual>
      <inertial mass="0.1">
        <inertia ixx='1' ixy='0' ixz='0' iyy='1' iyz='0' izz='1'/>
      </inertial>
    </link>


  <link name="LF_up_leg_rot_x" >
      <collision name="geom">
        <geometry>
          <cylinder radius="0.020" length="0.075"/>
        </geometry>
      </collision>
   
      <visual name="visual">	
        <geometry>
          <cylinder radius="0.020" length="0.075"/>
        </geometry>
      </visual>
      <inertial mass="0.1">
        <inertia ixx='1' ixy='0' ixz='0' iyy='1' iyz='0' izz='1'/>
      </inertial>
    </link>


  <link name="RB_up_leg_rot_x" >
      <collision name="geom">
        <geometry>
          <cylinder radius="0.020" length="0.075"/>
        </geometry>
      </collision>
   
      <visual name="visual">
        <geometry>
          <cylinder radius="0.020" length="0.075"/>
        </geometry>
      </visual>
      <inertial mass="0.1">
        <inertia ixx='1' ixy='0' ixz='0' iyy='1' iyz='0' izz='1'/>
      </inertial>
    </link>


  <link name="LB_up_leg_rot_x" >
      <collision name="geom">
        <geometry>
          <cylinder radius="0.020" length="0.075"/>
        </geometry>
      </collision> 
      <visual name="visual">
        <geometry>
          <cylinder radius="0.020" length="0.075"/>
        </geometry>
      </visual>
      <inertial mass="0.1">
        <inertia ixx='1' ixy='0' ixz='0' iyy='1' iyz='0' izz='1'/>
      </inertial>
    </link>



<!--Part inferior de la pota, amb rotacio al voltant de l'eix x-->

  <link name="RF_down_leg" >
      <collision name="geom">
	<origin pose="0 0 -0.0275 0 0 0"/>
        <geometry>
          <cylinder radius="0.020" length="0.080"/>
        </geometry>
      </collision>
   
      <visual name="visual">
	<origin pose="0 0 -0.0275 0 0 0"/>
        <geometry>
          <cylinder radius="0.020" length="0.080"/>
        </geometry>
      </visual>
      <inertial mass="0.1">
        <inertia ixx='1' ixy='0' ixz='0' iyy='1' iyz='0' izz='1'/>
      </inertial>
    </link>


  <link name="LF_down_leg" >
      <collision name="geom">
	<origin pose="0 0 -0.0275 0 0 0"/>
        <geometry>
          <cylinder radius="0.020" length="0.080"/>
        </geometry>
      </collision>
   
      <visual name="visual">
	<origin pose="0 0 -0.0275 0 0 0"/>
        <geometry>
          <cylinder radius="0.020" length="0.080"/>
        </geometry>
      </visual>
      <inertial mass="0.1">
        <inertia ixx='1' ixy='0' ixz='0' iyy='1' iyz='0' izz='1'/>
      </inertial>
    </link>


  <link name="RB_down_leg" >
      <collision name="geom">
	<origin pose="0 0 -0.0275 0 0 0"/>
        <geometry>
          <cylinder radius="0.020" length="0.080"/>
        </geometry>
      </collision>
   
      <visual name="visual">
	<origin pose="0 0 -0.0275 0 0 0"/>
        <geometry>
          <cylinder radius="0.020" length="0.080"/>
        </geometry>
      </visual>
      <inertial mass="0.1">
        <inertia ixx='1' ixy='0' ixz='0' iyy='1' iyz='0' izz='1'/>
      </inertial>
    </link>


  <link name="LB_down_leg" >
      <collision name="geom">
	<origin pose="0 0 -0.0275 0 0 0"/>
        <geometry>
          <cylinder radius="0.020" length="0.080"/>
        </geometry>
      </collision>
   
      <visual name="visual">
	<origin pose="0 0 -0.0275 0 0 0"/>
        <geometry>
          <cylinder radius="0.020" length="0.080"/>
        </geometry>
      </visual>
      <inertial mass="0.1">
        <inertia ixx='1' ixy='0' ixz='0' iyy='1' iyz='0' izz='1'/>
      </inertial>
    </link>


<!--Potes-->

  <link name="RF_paw" >
      <collision name="geom">
        <geometry>
          <sphere radius="0.015"/>
        </geometry>
      </collision>
   
      <visual name="visual">
        <geometry>
          <sphere radius="0.015"/>
        </geometry>
      </visual>
      <inertial mass="0.1">
        <inertia ixx='1' ixy='0' ixz='0' iyy='1' iyz='0' izz='1'/>
      </inertial>
    </link>


  <link name="LF_paw" >
      <collision name="geom">
        <geometry>
          <sphere radius="0.015"/>
        </geometry>
	<surface>
	  <friction>
            <ode mu='1.000000' mu2='1.000000'/>
          </friction>
	</surface>
      </collision>
      <visual name="visual">
        <geometry>
          <sphere radius="0.015"/>
        </geometry>
      </visual>
      <inertial mass="0.1">
        <inertia ixx='1' ixy='0' ixz='0' iyy='1' iyz='0' izz='1'/>
      </inertial>
    </link>


  <link name="RB_paw" >
      <collision name="geom">
        <geometry>
          <sphere radius="0.015"/>
        </geometry>
	<surface>
	  <friction>
            <ode mu='1.000000' mu2='1.000000'/>
          </friction>
	</surface>
      </collision>
      <visual name="visual">
        <geometry>
          <sphere radius="0.015"/>
        </geometry>
      </visual>
      <inertial mass="0.1">
        <inertia ixx='1' ixy='0' ixz='0' iyy='1' iyz='0' izz='1'/>
      </inertial>
    </link>


  <link name="LB_paw" >
      <collision name="geom">
        <geometry>
          <sphere radius="0.015"/>
        </geometry>
	<surface>
	  <friction>
            <ode mu='1.000000' mu2='1.000000'/>
          </friction>
	</surface>
      </collision>
      <visual name="visual">
        <geometry>
          <sphere radius="0.015"/>
        </geometry>
      </visual>
      <inertial mass="0.1">
        <inertia ixx='1' ixy='0' ixz='0' iyy='1' iyz='0' izz='1'/>
      </inertial>
    </link>


<!--Joints-->

<!-- Articulacio l'espatlla en revolucio de [-9,91] graus al voltant de eix y -->

<!-- Articulacio l'espatlla en revolucio de [-134,120] les dretes i [-120,134] les esquerres graus al voltant de eix x -->

<!-- Articulacio del genoll en revolucio de [-29,119] graus al voltant de eix x -->

<!-- Pota dreta frontal (ordenat per espatlla eix y, espatlla eix x, inferior) -->

    <joint type="revolute" name="RF_up_leg_rot_y_joint">
      <origin pose="0.055 0.065 0 0 0 0"/>
      <axis xyz="0 1 0">
        <limit effort="1000.0" lower="-1.58825" upper="0.15708" velocity="0.5"/> 
      </axis>
      <parent link="base_link"/>
      <child link="RF_up_leg_rot_y"/>
    </joint>

    <joint type="revolute" name="RF_up_leg_rot_x_joint">
      <origin pose="0 0 -0.0275 0 0 0"/>
      
      <axis xyz="1 0 0">
         <limit effort="1000.0" lower="-2.3387" upper="2.094" velocity="0.5"/> 
      </axis>
      <parent link="RF_up_leg_rot_y"/>
      <child link="RF_up_leg_rot_x"/>
    </joint>

    <joint type="revolute" name="RF_down_leg_joint">
      <axis xyz="1 0 0">
        <limit effort="1000.0" lower="-0.506" upper="2.0768" velocity="0.5"/>
      </axis>
      <origin pose="0 0.009 -0.0375 0.38025 0 0"/>
      <parent link="RF_up_leg_rot_x"/>
      <child link="RF_down_leg"/>
    </joint>


<!-- Pota esquerra frontal (ordenat per superior eix y, sup. eix x, inferior) -->

    <joint type="revolute" name="LF_up_leg_rot_y_joint">
      <origin pose="-0.055 0.065 0 0 0 0"/>
      <axis xyz="0 1 0">
         <limit effort="1000.0" lower="-0.15708" upper="1.58825" velocity="0.5"/> 
      </axis>
      <parent link="base_link"/>
      <child link="LF_up_leg_rot_y"/>
    </joint>

    <joint type="revolute" name="LF_up_leg_rot_x_joint">
      <origin pose="0 0 -0.0275 0 0 0"/>
      <axis xyz="1 0 0">
        <limit effort="1000.0" lower="-2.094" upper="2.3387" velocity="0.5"/>
      </axis> 
      <parent link="LF_up_leg_rot_y"/>
      <child link="LF_up_leg_rot_x"/>
    </joint>

    <joint type="revolute" name="LF_down_leg_joint">
      <axis xyz="1 0 0">
        <limit effort="1000.0" lower="-0.506" upper="2.0768" velocity="0.5"/>
      </axis>
      <origin pose="0 0.009 -0.0375 0.38025 0 0"/>
      <parent link="LF_up_leg_rot_x"/>
      <child link="LF_down_leg"/>
    </joint>


<!-- Pota dreta posterior (ordenat per superior eix y, sup. eix x, inferior) -->

    <joint type="revolute" name="RB_up_leg_rot_y_joint">
      <origin pose="0.055 -0.065 0 0 0 0"/>
      <axis xyz="0 1 0">
        <limit effort="1000.0" lower="-1.58825" upper="0.15708" velocity="0.5"/> 
      </axis>
      <parent link="base_link"/>
      <child link="RB_up_leg_rot_y"/>
    </joint>

    <joint type="revolute" name="RB_up_leg_rot_x_joint">
      <origin pose="0 0 -0.0275 0 0 0"/>
      <axis xyz="1 0 0">
        <limit effort="1000.0" lower="-2.3387" upper="2.094" velocity="0.5"/>
      </axis>
      <parent link="RB_up_leg_rot_y"/>
      <child link="RB_up_leg_rot_x"/>
    </joint>

    <joint type="revolute" name="RB_down_leg_joint">
      <axis xyz="1 0 0">
        <limit effort="1000.0" lower="-0.506" upper="2.0768" velocity="0.5"/>
      </axis>
      <origin pose="0 -0.009 -0.0375 -0.38025 0 0"/>
      <parent link="RB_up_leg_rot_x"/>
      <child link="RB_down_leg"/>
    </joint>


<!-- Pota esquerra posterior (ordenat per superior eix y, sup. eix x, inferior) -->

    <joint type="revolute" name="LB_up_leg_rot_y_joint">
      <origin pose="-0.055 -0.065 0 0 0 0"/>
      <axis xyz="0 1 0">
        <limit effort="1000.0" lower="-0.15708" upper="1.58825" velocity="0.5"/> 
      </axis>
      <parent link="base_link"/>
      <child link="LB_up_leg_rot_y"/>
    </joint>

    <joint type="revolute" name="LB_up_leg_rot_x_joint">
      <origin pose="0 0 -0.0275 0 0 0"/>
      <axis xyz="1 0 0">
        <limit effort="1000.0" lower="-2.094" upper="2.3387" velocity="0.5"/>
      </axis>
      <parent link="LB_up_leg_rot_y"/>
      <child link="LB_up_leg_rot_x"/>
    </joint>

    <joint type="revolute" name="LB_down_leg_joint">
      <axis xyz="1 0 0">
        <limit effort="1000.0" lower="-0.506" upper="2.0768" velocity="0.5"/>
      </axis>
      <origin pose="-0 -0.009 -0.0375 -0.38025 0 0"/>
      <parent link="LB_up_leg_rot_x"/>
      <child link="LB_down_leg"/>
    </joint>


<!-- Els peus son fixes -->
<!--    <joint type="fixed" name="RF_paw_joint">
      <origin pose="0 0 -0.070 0 0 0"/>
      <parent link="RF_down_leg"/>
      <child link="RF_paw"/>
    </joint>

    <joint type="fixed" name="LF_paw_joint">
      <origin pose="0 0 -0.070 0 0 0"/>
      <parent link="LF_down_leg"/>
      <child link="LF_paw"/>
    </joint>

    <joint type="fixed" name="RB_paw_joint">
      <origin pose="0 0 -0.070 0 0 0"/>
      <parent link="RB_down_leg"/>
      <child link="RB_paw"/>
    </joint>

    <joint type="fixed" name="LB_paw_joint">
      <origin pose="0 0 -0.070 0 0 0"/>
      <parent link="LB_down_leg"/>
      <child link="LB_paw"/>
    </joint>
-->
  </gazebo>
</model>
</gazebo>
